127.0.0.1 - - [06/Aug/2025 13:11:55] "GET / HTTP/1.1" 200 -
127.0.0.1 - - [06/Aug/2025 13:11:55] code 404, message File not found
127.0.0.1 - - [06/Aug/2025 13:11:55] "GET /favicon.ico HTTP/1.1" 404 -
127.0.0.1 - - [06/Aug/2025 15:21:06] "GET / HTTP/1.1" 200 -
127.0.0.1 - - [06/Aug/2025 15:21:23] "GET /start.js HTTP/1.1" 200 -
Traceback (most recent call last):
  File "/Applications/Xcode.app/Contents/Developer/Library/Frameworks/Python3.framework/Versions/3.9/lib/python3.9/runpy.py", line 197, in _run_module_as_main
    return _run_code(code, main_globals, None,
  File "/Applications/Xcode.app/Contents/Developer/Library/Frameworks/Python3.framework/Versions/3.9/lib/python3.9/runpy.py", line 87, in _run_code
    exec(code, run_globals)
  File "/Applications/Xcode.app/Contents/Developer/Library/Frameworks/Python3.framework/Versions/3.9/lib/python3.9/http/server.py", line 1297, in <module>
    test(
  File "/Applications/Xcode.app/Contents/Developer/Library/Frameworks/Python3.framework/Versions/3.9/lib/python3.9/http/server.py", line 1252, in test
    with ServerClass(addr, HandlerClass) as httpd:
  File "/Applications/Xcode.app/Contents/Developer/Library/Frameworks/Python3.framework/Versions/3.9/lib/python3.9/socketserver.py", line 452, in __init__
    self.server_bind()
  File "/Applications/Xcode.app/Contents/Developer/Library/Frameworks/Python3.framework/Versions/3.9/lib/python3.9/http/server.py", line 1295, in server_bind
    return super().server_bind()
  File "/Applications/Xcode.app/Contents/Developer/Library/Frameworks/Python3.framework/Versions/3.9/lib/python3.9/http/server.py", line 138, in server_bind
    socketserver.TCPServer.server_bind(self)
  File "/Applications/Xcode.app/Contents/Developer/Library/Frameworks/Python3.framework/Versions/3.9/lib/python3.9/socketserver.py", line 466, in server_bind
    self.socket.bind(self.server_address)
OSError: [Errno 48] Address already in use
